Workbook

Sheet MasterCMCopy
A1: Min SDK Version | B1: Max SDK Version | C1: eForms SDK ID | D1: Name | E1: BT ID | F1: Is Node? | G1: Is Field? | H1: parentId | I1: parentNodeId | J1: TriplesMap Status | K1: Default Mapping Group (Generated) | L1: Mapping Group ID | M1: Module | N1: Absolute XPath | O1: XPath Condition | P1: Relative XPath | Q1: attributeName | R1: attributeOf | S1: repeatable | T1: repeatable/value | U1: type | V1: legalType | W1: codeList/id | X1: Class Path | Y1: Property Path | Z1: Mapping Notes (public) | AA1: Editorial Notes (private) | AB1: Feedback Notes (private)
A2: 1.4 | C2: ND-ProcedureFeaturesUnpublish | F2: =IF(C2="", "", OR( LEFT(C2,3)="ND-", LEFT(C2,4)="[ND-")) -> TRUE | G2: =IF(C2="", "", NOT(F2)) -> FALSE | H2: ND-ProcedureTenderingProcess | J2: TODO | L2: MG-Procedure-concernsMaskedObject-NonPublishedInformation | M2: 6p | N2: /*/cac:TenderingProcess/ext:UBLExtensions/ext:UBLExtension/ext:ExtensionContent/efext:EformsExtension/efac:FieldsPrivacy[efbc:FieldIdentifierCode/text()='pro-fea'] | P2: ext:UBLExtensions/ext:UBLExtension/ext:ExtensionContent/efext:EformsExtension/efac:FieldsPrivacy[efbc:FieldIdentifierCode/text()='pro-fea'] | S2: FALSE | X2: epo:NonPublishedInformation / epo:Procedure | Y2: ?this epo:concernsMaskedObject ?value .
A3: 1.4 | C3: ND-ProcedureFeaturesUnpublish | F3: =IF(C3="", "", OR( LEFT(C3,3)="ND-", LEFT(C3,4)="[ND-")) -> TRUE | G3: =IF(C3="", "", NOT(F3)) -> FALSE | H3: ND-ProcedureTenderingProcess | J3: TODO | L3: MG-Notice-concernsNotice-NonPublishedInformation | M3: 6p | N3: /*/cac:TenderingProcess/ext:UBLExtensions/ext:UBLExtension/ext:ExtensionContent/efext:EformsExtension/efac:FieldsPrivacy[efbc:FieldIdentifierCode/text()='pro-fea'] | P3: ext:UBLExtensions/ext:UBLExtension/ext:ExtensionContent/efext:EformsExtension/efac:FieldsPrivacy[efbc:FieldIdentifierCode/text()='pro-fea'] | S3: FALSE | X3: epo:NonPublishedInformation / epo:Notice | Y3: ?this epo:concernsNotice ?value .
A4: 1.4 | C4: BT-195(BT-88)-Procedure | D4: Unpublished Identifier | E4: BT-195 | F4: =IF(C4="", "", OR( LEFT(C4,3)="ND-", LEFT(C4,4)="[ND-")) -> FALSE | G4: =IF(C4="", "", NOT(F4)) -> TRUE | I4: ND-ProcedureFeaturesUnpublish | J4: TODO | L4: MG-NonPublishedInformation | M4: 6p | N4: /*/cac:TenderingProcess/ext:UBLExtensions/ext:UBLExtension/ext:ExtensionContent/efext:EformsExtension/efac:FieldsPrivacy[efbc:FieldIdentifierCode/text()='pro-fea']/efbc:FieldIdentifierCode | O4: efbc:FieldIdentifierCode/text() = 'pro-fea' | P4: efbc:FieldIdentifierCode | T4: FALSE | U4: code | V4: IDENTIFIER | W4: non-publication-identifier | X4: epo:NonPublishedInformation | Y4: ?this epo:hasMaskableProperty <http://data.europa.eu/a4g/ontology#hasMainFeature> .
A5: 1.4 | C5: BT-196(BT-88)-Procedure | D5: Unpublished Justification Description | E5: BT-196 | F5: =IF(C5="", "", OR( LEFT(C5,3)="ND-", LEFT(C5,4)="[ND-")) -> FALSE | G5: =IF(C5="", "", NOT(F5)) -> TRUE | I5: ND-ProcedureFeaturesUnpublish | J5: TODO | L5: MG-NonPublishedInformation | M5: 6p | N5: /*/cac:TenderingProcess/ext:UBLExtensions/ext:UBLExtension/ext:ExtensionContent/efext:EformsExtension/efac:FieldsPrivacy[efbc:FieldIdentifierCode/text()='pro-fea']/efbc:ReasonDescription | P5: efbc:ReasonDescription | T5: FALSE | U5: text-multilingual | V5: TEXT | X5: epo:NonPublishedInformation / rdf:langString | Y5: ?this epo:hasConfidentialityJustification ?value .
A6: 1.4 | C6: BT-197(BT-88)-Procedure | D6: Unpublished Justification Code | E6: BT-197 | F6: =IF(C6="", "", OR( LEFT(C6,3)="ND-", LEFT(C6,4)="[ND-")) -> FALSE | G6: =IF(C6="", "", NOT(F6)) -> TRUE | I6: ND-ProcedureFeaturesUnpublish | J6: TODO | L6: MG-NonPublishedInformation | M6: 6p | N6: /*/cac:TenderingProcess/ext:UBLExtensions/ext:UBLExtension/ext:ExtensionContent/efext:EformsExtension/efac:FieldsPrivacy[efbc:FieldIdentifierCode/text()='pro-fea']/cbc:ReasonCode | P6: cbc:ReasonCode | T6: FALSE | U6: code | V6: CODE | W6: non-publication-justification | X6: epo:NonPublishedInformation / at-voc:non-publication-justification | Y6: ?this epo:hasNonPublicationJustification ?value .
A7: 1.4 | B7: 1.5 | C7: BT-198(BT-88)-Procedure | D7: Unpublished Accessibility Date | E7: BT-198 | F7: =IF(C7="", "", OR( LEFT(C7,3)="ND-", LEFT(C7,4)="[ND-")) -> FALSE | G7: =IF(C7="", "", NOT(F7)) -> TRUE | I7: ND-ProcedureFeaturesUnpublish | J7: TODO | L7: MG-NonPublishedInformation | M7: 6p | N7: /*/cac:TenderingProcess/ext:UBLExtensions/ext:UBLExtension/ext:ExtensionContent/efext:EformsExtension/efac:FieldsPrivacy[efbc:FieldIdentifierCode/text()='pro-fea']/efbc:PublicationDate | P7: efbc:PublicationDate | T7: FALSE | U7: date | V7: DATE | X7: epo:NonPublishedInformation / xsd:date | Y7: ?this epo:hasAccessibilityDate ?value .
A8: 1.6 | C8: BT-198(BT-88)-Procedure | D8: Unpublished Access Date | E8: BT-198 | F8: =IF(C8="", "", OR( LEFT(C8,3)="ND-", LEFT(C8,4)="[ND-")) -> FALSE | G8: =IF(C8="", "", NOT(F8)) -> TRUE | I8: ND-ProcedureFeaturesUnpublish | J8: TODO | L8: MG-NonPublishedInformation | M8: 6p | N8: /*/cac:TenderingProcess/ext:UBLExtensions/ext:UBLExtension/ext:ExtensionContent/efext:EformsExtension/efac:FieldsPrivacy[efbc:FieldIdentifierCode/text()='pro-fea']/efbc:PublicationDate | P8: efbc:PublicationDate | T8: FALSE | U8: date | V8: DATE | X8: epo:NonPublishedInformation / xsd:date | Y8: ?this epo:hasAccessibilityDate ?value .
A9: 1.4 | C9: ND-ProcedureTypeUnpublish | F9: =IF(C9="", "", OR( LEFT(C9,3)="ND-", LEFT(C9,4)="[ND-")) -> TRUE | G9: =IF(C9="", "", NOT(F9)) -> FALSE | H9: ND-ProcedureTenderingProcess | J9: TODO | L9: MG-Procedure-concernsMaskedObject-NonPublishedInformation | M9: 6p | N9: /*/cac:TenderingProcess/ext:UBLExtensions/ext:UBLExtension/ext:ExtensionContent/efext:EformsExtension/efac:FieldsPrivacy[efbc:FieldIdentifierCode/text()='pro-typ'] | P9: ext:UBLExtensions/ext:UBLExtension/ext:ExtensionContent/efext:EformsExtension/efac:FieldsPrivacy[efbc:FieldIdentifierCode/text()='pro-typ'] | S9: FALSE | X9: epo:NonPublishedInformation / epo:Procedure | Y9: ?this epo:concernsMaskedObject ?value .
A10: 1.4 | C10: ND-ProcedureTypeUnpublish | F10: =IF(C10="", "", OR( LEFT(C10,3)="ND-", LEFT(C10,4)="[ND-")) -> TRUE | G10: =IF(C10="", "", NOT(F10)) -> FALSE | H10: ND-ProcedureTenderingProcess | J10: TODO | L10: MG-Notice-concernsNotice-NonPublishedInformation | M10: 6p | N10: /*/cac:TenderingProcess/ext:UBLExtensions/ext:UBLExtension/ext:ExtensionContent/efext:EformsExtension/efac:FieldsPrivacy[efbc:FieldIdentifierCode/text()='pro-typ'] | P10: ext:UBLExtensions/ext:UBLExtension/ext:ExtensionContent/efext:EformsExtension/efac:FieldsPrivacy[efbc:FieldIdentifierCode/text()='pro-typ'] | S10: FALSE | X10: epo:NonPublishedInformation / epo:Notice | Y10: ?this epo:concernsNotice ?value .
A11: 1.4 | C11: BT-195(BT-105)-Procedure | D11: Unpublished Identifier | E11: BT-195 | F11: =IF(C11="", "", OR( LEFT(C11,3)="ND-", LEFT(C11,4)="[ND-")) -> FALSE | G11: =IF(C11="", "", NOT(F11)) -> TRUE | I11: ND-ProcedureTypeUnpublish | J11: TODO | L11: MG-NonPublishedInformation | M11: 6p | N11: /*/cac:TenderingProcess/ext:UBLExtensions/ext:UBLExtension/ext:ExtensionContent/efext:EformsExtension/efac:FieldsPrivacy[efbc:FieldIdentifierCode/text()='pro-typ']/efbc:FieldIdentifierCode | O11: efbc:FieldIdentifierCode/text() = 'pro-typ' | P11: efbc:FieldIdentifierCode | T11: FALSE | U11: code | V11: IDENTIFIER | W11: non-publication-identifier | X11: epo:NonPublishedInformation | Y11: ?this epo:hasMaskableProperty <http://data.europa.eu/a4g/ontology#hasProcedureType> .
A12: 1.4 | C12: BT-196(BT-105)-Procedure | D12: Unpublished Justification Description | E12: BT-196 | F12: =IF(C12="", "", OR( LEFT(C12,3)="ND-", LEFT(C12,4)="[ND-")) -> FALSE | G12: =IF(C12="", "", NOT(F12)) -> TRUE | I12: ND-ProcedureTypeUnpublish | J12: TODO | L12: MG-NonPublishedInformation | M12: 6p | N12: /*/cac:TenderingProcess/ext:UBLExtensions/ext:UBLExtension/ext:ExtensionContent/efext:EformsExtension/efac:FieldsPrivacy[efbc:FieldIdentifierCode/text()='pro-typ']/efbc:ReasonDescription | P12: efbc:ReasonDescription | T12: FALSE | U12: text-multilingual | V12: TEXT | X12: epo:NonPublishedInformation / rdf:langString | Y12: ?this epo:hasConfidentialityJustification ?value .
A13: 1.4 | C13: BT-197(BT-105)-Procedure | D13: Unpublished Justification Code | E13: BT-197 | F13: =IF(C13="", "", OR( LEFT(C13,3)="ND-", LEFT(C13,4)="[ND-")) -> FALSE | G13: =IF(C13="", "", NOT(F13)) -> TRUE | I13: ND-ProcedureTypeUnpublish | J13: TODO | L13: MG-NonPublishedInformation | M13: 6p | N13: /*/cac:TenderingProcess/ext:UBLExtensions/ext:UBLExtension/ext:ExtensionContent/efext:EformsExtension/efac:FieldsPrivacy[efbc:FieldIdentifierCode/text()='pro-typ']/cbc:ReasonCode | P13: cbc:ReasonCode | T13: FALSE | U13: code | V13: CODE | W13: non-publication-justification | X13: epo:NonPublishedInformation / at-voc:non-publication-justification | Y13: ?this epo:hasNonPublicationJustification ?value .
A14: 1.4 | B14: 1.5 | C14: BT-198(BT-105)-Procedure | D14: Unpublished Accessibility Date | E14: BT-198 | F14: =IF(C14="", "", OR( LEFT(C14,3)="ND-", LEFT(C14,4)="[ND-")) -> FALSE | G14: =IF(C14="", "", NOT(F14)) -> TRUE | I14: ND-ProcedureTypeUnpublish | J14: TODO | L14: MG-NonPublishedInformation | M14: 6p | N14: /*/cac:TenderingProcess/ext:UBLExtensions/ext:UBLExtension/ext:ExtensionContent/efext:EformsExtension/efac:FieldsPrivacy[efbc:FieldIdentifierCode/text()='pro-typ']/efbc:PublicationDate | P14: efbc:PublicationDate | T14: FALSE | U14: date | V14: DATE | X14: epo:NonPublishedInformation / xsd:date | Y14: ?this epo:hasAccessibilityDate ?value .
A15: 1.6 | C15: BT-198(BT-105)-Procedure | D15: Unpublished Access Date | E15: BT-198 | F15: =IF(C15="", "", OR( LEFT(C15,3)="ND-", LEFT(C15,4)="[ND-")) -> FALSE | G15: =IF(C15="", "", NOT(F15)) -> TRUE | I15: ND-ProcedureTypeUnpublish | J15: TODO | L15: MG-NonPublishedInformation | M15: 6p | N15: /*/cac:TenderingProcess/ext:UBLExtensions/ext:UBLExtension/ext:ExtensionContent/efext:EformsExtension/efac:FieldsPrivacy[efbc:FieldIdentifierCode/text()='pro-typ']/efbc:PublicationDate | P15: efbc:PublicationDate | T15: FALSE | U15: date | V15: DATE | X15: epo:NonPublishedInformation / xsd:date | Y15: ?this epo:hasAccessibilityDate ?value .
A16: 1.4 | C16: ND-ProcedureAcceleratedUnpublish | F16: =IF(C16="", "", OR( LEFT(C16,3)="ND-", LEFT(C16,4)="[ND-")) -> TRUE | G16: =IF(C16="", "", NOT(F16)) -> FALSE | H16: ND-AcceleratedProcedure | J16: DONE-RESERVATIONS | L16: MG-Procedure-concernsMaskedObject-NonPublishedInformation | M16: 6p | N16: /*/cac:TenderingProcess/cac:ProcessJustification[cbc:ProcessReasonCode/@listName='accelerated-procedure']/ext:UBLExtensions/ext:UBLExtension/ext:ExtensionContent/efext:EformsExtension/efac:FieldsPrivacy[efbc:FieldIdentifierCode/text()='pro-acc'] | P16: ext:UBLExtensions/ext:UBLExtension/ext:ExtensionContent/efext:EformsExtension/efac:FieldsPrivacy[efbc:FieldIdentifierCode/text()='pro-acc'] | S16: FALSE | X16: epo:NonPublishedInformation / epo:Procedure | Y16: ?this epo:concernsMaskedObject ?value .
A17: 1.4 | C17: ND-ProcedureAcceleratedUnpublish | F17: =IF(C17="", "", OR( LEFT(C17,3)="ND-", LEFT(C17,4)="[ND-")) -> TRUE | G17: =IF(C17="", "", NOT(F17)) -> FALSE | H17: ND-AcceleratedProcedure | J17: DONE-RESERVATIONS | L17: MG-Notice-concernsNotice-NonPublishedInformation | M17: 6p | N17: /*/cac:TenderingProcess/cac:ProcessJustification[cbc:ProcessReasonCode/@listName='accelerated-procedure']/ext:UBLExtensions/ext:UBLExtension/ext:ExtensionContent/efext:EformsExtension/efac:FieldsPrivacy[efbc:FieldIdentifierCode/text()='pro-acc'] | P17: ext:UBLExtensions/ext:UBLExtension/ext:ExtensionContent/efext:EformsExtension/efac:FieldsPrivacy[efbc:FieldIdentifierCode/text()='pro-acc'] | S17: FALSE | X17: epo:NonPublishedInformation / epo:Notice | Y17: ?this epo:concernsNotice ?value .
A18: 1.4 | C18: BT-195(BT-106)-Procedure | D18: Unpublished Identifier | E18: BT-195 | F18: =IF(C18="", "", OR( LEFT(C18,3)="ND-", LEFT(C18,4)="[ND-")) -> FALSE | G18: =IF(C18="", "", NOT(F18)) -> TRUE | I18: ND-ProcedureAcceleratedUnpublish | J18: DONE | L18: MG-NonPublishedInformation | M18: 6p | N18: /*/cac:TenderingProcess/cac:ProcessJustification[cbc:ProcessReasonCode/@listName='accelerated-procedure']/ext:UBLExtensions/ext:UBLExtension/ext:ExtensionContent/efext:EformsExtension/efac:FieldsPrivacy[efbc:FieldIdentifierCode/text()='pro-acc']/efbc:FieldIdentifierCode | O18: efbc:FieldIdentifierCode/text() = 'pro-acc' | P18: efbc:FieldIdentifierCode | T18: FALSE | U18: code | V18: IDENTIFIER | W18: non-publication-identifier | X18: epo:NonPublishedInformation | Y18: ?this epo:hasMaskableProperty <http://data.europa.eu/a4g/ontology#isAccelerated> .
A19: 1.4 | C19: BT-196(BT-106)-Procedure | D19: Unpublished Justification Description | E19: BT-196 | F19: =IF(C19="", "", OR( LEFT(C19,3)="ND-", LEFT(C19,4)="[ND-")) -> FALSE | G19: =IF(C19="", "", NOT(F19)) -> TRUE | I19: ND-ProcedureAcceleratedUnpublish | J19: DONE | L19: MG-NonPublishedInformation | M19: 6p | N19: /*/cac:TenderingProcess/cac:ProcessJustification[cbc:ProcessReasonCode/@listName='accelerated-procedure']/ext:UBLExtensions/ext:UBLExtension/ext:ExtensionContent/efext:EformsExtension/efac:FieldsPrivacy[efbc:FieldIdentifierCode/text()='pro-acc']/efbc:ReasonDescription | P19: efbc:ReasonDescription | T19: FALSE | U19: text-multilingual | V19: TEXT | X19: epo:NonPublishedInformation / rdf:langString | Y19: ?this epo:hasConfidentialityJustification ?value .
A20: 1.4 | C20: BT-197(BT-106)-Procedure | D20: Unpublished Justification Code | E20: BT-197 | F20: =IF(C20="", "", OR( LEFT(C20,3)="ND-", LEFT(C20,4)="[ND-")) -> FALSE | G20: =IF(C20="", "", NOT(F20)) -> TRUE | I20: ND-ProcedureAcceleratedUnpublish | J20: DONE | L20: MG-NonPublishedInformation | M20: 6p | N20: /*/cac:TenderingProcess/cac:ProcessJustification[cbc:ProcessReasonCode/@listName='accelerated-procedure']/ext:UBLExtensions/ext:UBLExtension/ext:ExtensionContent/efext:EformsExtension/efac:FieldsPrivacy[efbc:FieldIdentifierCode/text()='pro-acc']/cbc:ReasonCode | P20: cbc:ReasonCode | T20: FALSE | U20: code | V20: CODE | W20: non-publication-justification | X20: epo:NonPublishedInformation / at-voc:non-publication-justification | Y20: ?this epo:hasNonPublicationJustification ?value .
A21: 1.4 | B21: 1.5 | C21: BT-198(BT-106)-Procedure | D21: Unpublished Accessibility Date | E21: BT-198 | F21: =IF(C21="", "", OR( LEFT(C21,3)="ND-", LEFT(C21,4)="[ND-")) -> FALSE | G21: =IF(C21="", "", NOT(F21)) -> TRUE | I21: ND-ProcedureAcceleratedUnpublish | J21: DONE | L21: MG-NonPublishedInformation | M21: 6p | N21: /*/cac:TenderingProcess/cac:ProcessJustification[cbc:ProcessReasonCode/@listName='accelerated-procedure']/ext:UBLExtensions/ext:UBLExtension/ext:ExtensionContent/efext:EformsExtension/efac:FieldsPrivacy[efbc:FieldIdentifierCode/text()='pro-acc']/efbc:PublicationDate | P21: efbc:PublicationDate | T21: FALSE | U21: date | V21: DATE | X21: epo:NonPublishedInformation / xsd:date | Y21: ?this epo:hasAccessibilityDate ?value .
A22: 1.6 | C22: BT-198(BT-106)-Procedure | D22: Unpublished Access Date | E22: BT-198 | F22: =IF(C22="", "", OR( LEFT(C22,3)="ND-", LEFT(C22,4)="[ND-")) -> FALSE | G22: =IF(C22="", "", NOT(F22)) -> TRUE | I22: ND-ProcedureAcceleratedUnpublish | J22: DONE | L22: MG-NonPublishedInformation | M22: 6p | N22: /*/cac:TenderingProcess/cac:ProcessJustification[cbc:ProcessReasonCode/@listName='accelerated-procedure']/ext:UBLExtensions/ext:UBLExtension/ext:ExtensionContent/efext:EformsExtension/efac:FieldsPrivacy[efbc:FieldIdentifierCode/text()='pro-acc']/efbc:PublicationDate | P22: efbc:PublicationDate | T22: FALSE | U22: date | V22: DATE | X22: epo:NonPublishedInformation / xsd:date | Y22: ?this epo:hasAccessibilityDate ?value .
A23: 1.4 | C23: ND-ProcedureAcceleratedJustificationUnpublish | F23: =IF(C23="", "", OR( LEFT(C23,3)="ND-", LEFT(C23,4)="[ND-")) -> TRUE | G23: =IF(C23="", "", NOT(F23)) -> FALSE | H23: ND-AcceleratedProcedure | J23: TODO | L23: MG-Procedure-concernsMaskedObject-NonPublishedInformation | M23: 6p | N23: /*/cac:TenderingProcess/cac:ProcessJustification[cbc:ProcessReasonCode/@listName='accelerated-procedure']/ext:UBLExtensions/ext:UBLExtension/ext:ExtensionContent/efext:EformsExtension/efac:FieldsPrivacy[efbc:FieldIdentifierCode/text()='pro-acc-jus'] | P23: ext:UBLExtensions/ext:UBLExtension/ext:ExtensionContent/efext:EformsExtension/efac:FieldsPrivacy[efbc:FieldIdentifierCode/text()='pro-acc-jus'] | S23: FALSE | X23: epo:NonPublishedInformation / epo:Procedure | Y23: ?this epo:concernsMaskedObject ?value .
A24: 1.4 | C24: ND-ProcedureAcceleratedJustificationUnpublish | F24: =IF(C24="", "", OR( LEFT(C24,3)="ND-", LEFT(C24,4)="[ND-")) -> TRUE | G24: =IF(C24="", "", NOT(F24)) -> FALSE | H24: ND-AcceleratedProcedure | J24: TODO | L24: MG-Notice-concernsNotice-NonPublishedInformation | M24: 6p | N24: /*/cac:TenderingProcess/cac:ProcessJustification[cbc:ProcessReasonCode/@listName='accelerated-procedure']/ext:UBLExtensions/ext:UBLExtension/ext:ExtensionContent/efext:EformsExtension/efac:FieldsPrivacy[efbc:FieldIdentifierCode/text()='pro-acc-jus'] | P24: ext:UBLExtensions/ext:UBLExtension/ext:ExtensionContent/efext:EformsExtension/efac:FieldsPrivacy[efbc:FieldIdentifierCode/text()='pro-acc-jus'] | S24: FALSE | X24: epo:NonPublishedInformation / epo:Notice | Y24: ?this epo:concernsNotice ?value .
A25: 1.4 | C25: BT-195(BT-1351)-Procedure | D25: Unpublished Identifier | E25: BT-195 | F25: =IF(C25="", "", OR( LEFT(C25,3)="ND-", LEFT(C25,4)="[ND-")) -> FALSE | G25: =IF(C25="", "", NOT(F25)) -> TRUE | I25: ND-ProcedureAcceleratedJustificationUnpublish | J25: TODO | L25: MG-NonPublishedInformation | M25: 6p | N25: /*/cac:TenderingProcess/cac:ProcessJustification[cbc:ProcessReasonCode/@listName='accelerated-procedure']/ext:UBLExtensions/ext:UBLExtension/ext:ExtensionContent/efext:EformsExtension/efac:FieldsPrivacy[efbc:FieldIdentifierCode/text()='pro-acc-jus']/efbc:FieldIdentifierCode | O25: efbc:FieldIdentifierCode/text() = 'pro-acc-jus' | P25: efbc:FieldIdentifierCode | T25: FALSE | U25: code | V25: IDENTIFIER | W25: non-publication-identifier | X25: epo:NonPublishedInformation | Y25: ?this epo:hasMaskableProperty <http://data.europa.eu/a4g/ontology#hasAcceleratedProcedureJustification> .
A26: 1.4 | C26: BT-196(BT-1351)-Procedure | D26: Unpublished Justification Description | E26: BT-196 | F26: =IF(C26="", "", OR( LEFT(C26,3)="ND-", LEFT(C26,4)="[ND-")) -> FALSE | G26: =IF(C26="", "", NOT(F26)) -> TRUE | I26: ND-ProcedureAcceleratedJustificationUnpublish | J26: TODO | L26: MG-NonPublishedInformation | M26: 6p | N26: /*/cac:TenderingProcess/cac:ProcessJustification[cbc:ProcessReasonCode/@listName='accelerated-procedure']/ext:UBLExtensions/ext:UBLExtension/ext:ExtensionContent/efext:EformsExtension/efac:FieldsPrivacy[efbc:FieldIdentifierCode/text()='pro-acc-jus']/efbc:ReasonDescription | P26: efbc:ReasonDescription | T26: FALSE | U26: text-multilingual | V26: TEXT | X26: epo:NonPublishedInformation / rdf:langString | Y26: ?this epo:hasConfidentialityJustification ?value .
A27: 1.4 | C27: BT-197(BT-1351)-Procedure | D27: Unpublished Justification Code | E27: BT-197 | F27: =IF(C27="", "", OR( LEFT(C27,3)="ND-", LEFT(C27,4)="[ND-")) -> FALSE | G27: =IF(C27="", "", NOT(F27)) -> TRUE | I27: ND-ProcedureAcceleratedJustificationUnpublish | J27: TODO | L27: MG-NonPublishedInformation | M27: 6p | N27: /*/cac:TenderingProcess/cac:ProcessJustification[cbc:ProcessReasonCode/@listName='accelerated-procedure']/ext:UBLExtensions/ext:UBLExtension/ext:ExtensionContent/efext:EformsExtension/efac:FieldsPrivacy[efbc:FieldIdentifierCode/text()='pro-acc-jus']/cbc:ReasonCode | P27: cbc:ReasonCode | T27: FALSE | U27: code | V27: CODE | W27: non-publication-justification | X27: epo:NonPublishedInformation / at-voc:non-publication-justification | Y27: ?this epo:hasNonPublicationJustification ?value .
A28: 1.4 | B28: 1.5 | C28: BT-198(BT-1351)-Procedure | D28: Unpublished Accessibility Date | E28: BT-198 | F28: =IF(C28="", "", OR( LEFT(C28,3)="ND-", LEFT(C28,4)="[ND-")) -> FALSE | G28: =IF(C28="", "", NOT(F28)) -> TRUE | I28: ND-ProcedureAcceleratedJustificationUnpublish | J28: TODO | L28: MG-NonPublishedInformation | M28: 6p | N28: /*/cac:TenderingProcess/cac:ProcessJustification[cbc:ProcessReasonCode/@listName='accelerated-procedure']/ext:UBLExtensions/ext:UBLExtension/ext:ExtensionContent/efext:EformsExtension/efac:FieldsPrivacy[efbc:FieldIdentifierCode/text()='pro-acc-jus']/efbc:PublicationDate | P28: efbc:PublicationDate | T28: FALSE | U28: date | V28: DATE | X28: epo:NonPublishedInformation / xsd:date | Y28: ?this epo:hasAccessibilityDate ?value .
A29: 1.6 | C29: BT-198(BT-1351)-Procedure | D29: Unpublished Access Date | E29: BT-198 | F29: =IF(C29="", "", OR( LEFT(C29,3)="ND-", LEFT(C29,4)="[ND-")) -> FALSE | G29: =IF(C29="", "", NOT(F29)) -> TRUE | I29: ND-ProcedureAcceleratedJustificationUnpublish | J29: TODO | L29: MG-NonPublishedInformation | M29: 6p | N29: /*/cac:TenderingProcess/cac:ProcessJustification[cbc:ProcessReasonCode/@listName='accelerated-procedure']/ext:UBLExtensions/ext:UBLExtension/ext:ExtensionContent/efext:EformsExtension/efac:FieldsPrivacy[efbc:FieldIdentifierCode/text()='pro-acc-jus']/efbc:PublicationDate | P29: efbc:PublicationDate | T29: FALSE | U29: date | V29: DATE | X29: epo:NonPublishedInformation / xsd:date | Y29: ?this epo:hasAccessibilityDate ?value .
A30: 1.4 | C30: ND-DirectAwardJustificationCodeUnpublish | F30: =IF(C30="", "", OR( LEFT(C30,3)="ND-", LEFT(C30,4)="[ND-")) -> TRUE | G30: =IF(C30="", "", NOT(F30)) -> FALSE | H30: ND-DirectAward | J30: TODO | L30: MG-DirectAwardTerm-concernsMaskedObject-NonPublishedInformation | M30: 6p | N30: /*/cac:TenderingProcess/cac:ProcessJustification[cbc:ProcessReasonCode/@listName='direct-award-justification']/ext:UBLExtensions/ext:UBLExtension/ext:ExtensionContent/efext:EformsExtension/efac:FieldsPrivacy[efbc:FieldIdentifierCode/text()='dir-awa-jus'] | P30: ext:UBLExtensions/ext:UBLExtension/ext:ExtensionContent/efext:EformsExtension/efac:FieldsPrivacy[efbc:FieldIdentifierCode/text()='dir-awa-jus'] | S30: FALSE | X30: epo:NonPublishedInformation / epo:DirectAwardTerm | Y30: ?this epo:concernsMaskedObject ?value .
A31: 1.4 | C31: ND-DirectAwardJustificationCodeUnpublish | F31: =IF(C31="", "", OR( LEFT(C31,3)="ND-", LEFT(C31,4)="[ND-")) -> TRUE | G31: =IF(C31="", "", NOT(F31)) -> FALSE | H31: ND-DirectAward | J31: TODO | L31: MG-Notice-concernsNotice-NonPublishedInformation | M31: 6p | N31: /*/cac:TenderingProcess/cac:ProcessJustification[cbc:ProcessReasonCode/@listName='direct-award-justification']/ext:UBLExtensions/ext:UBLExtension/ext:ExtensionContent/efext:EformsExtension/efac:FieldsPrivacy[efbc:FieldIdentifierCode/text()='dir-awa-jus'] | P31: ext:UBLExtensions/ext:UBLExtension/ext:ExtensionContent/efext:EformsExtension/efac:FieldsPrivacy[efbc:FieldIdentifierCode/text()='dir-awa-jus'] | S31: FALSE | X31: epo:NonPublishedInformation / epo:Notice | Y31: ?this epo:concernsNotice ?value .
A32: 1.4 | C32: ND-DirectAwardJustificationCodeUnpublish | F32: =IF(C32="", "", OR( LEFT(C32,3)="ND-", LEFT(C32,4)="[ND-")) -> TRUE | G32: =IF(C32="", "", NOT(F32)) -> FALSE | H32: ND-DirectAward | J32: TODO | L32: MG-DirectAwardTerm-isSubjectToTerm-Procedure | M32: 6p | N32: /*/cac:TenderingProcess/cac:ProcessJustification[cbc:ProcessReasonCode/@listName='direct-award-justification']/ext:UBLExtensions/ext:UBLExtension/ext:ExtensionContent/efext:EformsExtension/efac:FieldsPrivacy[efbc:FieldIdentifierCode/text()='dir-awa-jus'] | P32: ext:UBLExtensions/ext:UBLExtension/ext:ExtensionContent/efext:EformsExtension/efac:FieldsPrivacy[efbc:FieldIdentifierCode/text()='dir-awa-jus'] | S32: FALSE | X32: epo:Procedure / epo:DirectAwardTerm | Y32: ?this epo:isSubjectToTerm ?value .
A33: 1.4 | C33: BT-195(BT-136)-Procedure | D33: Unpublished Identifier | E33: BT-195 | F33: =IF(C33="", "", OR( LEFT(C33,3)="ND-", LEFT(C33,4)="[ND-")) -> FALSE | G33: =IF(C33="", "", NOT(F33)) -> TRUE | I33: ND-DirectAwardJustificationCodeUnpublish | J33: TODO | L33: MG-NonPublishedInformation | M33: 6p | N33: /*/cac:TenderingProcess/cac:ProcessJustification[cbc:ProcessReasonCode/@listName='direct-award-justification']/ext:UBLExtensions/ext:UBLExtension/ext:ExtensionContent/efext:EformsExtension/efac:FieldsPrivacy[efbc:FieldIdentifierCode/text()='dir-awa-jus']/efbc:FieldIdentifierCode | O33: efbc:FieldIdentifierCode/text() = 'dir-awa-jus' | P33: efbc:FieldIdentifierCode | T33: FALSE | U33: code | V33: IDENTIFIER | W33: non-publication-identifier | X33: epo:NonPublishedInformation | Y33: ?this epo:hasMaskableProperty <http://data.europa.eu/a4g/ontology#hasDirectAwardJustification> .
A34: 1.4 | C34: BT-196(BT-136)-Procedure | D34: Unpublished Justification Description | E34: BT-196 | F34: =IF(C34="", "", OR( LEFT(C34,3)="ND-", LEFT(C34,4)="[ND-")) -> FALSE | G34: =IF(C34="", "", NOT(F34)) -> TRUE | I34: ND-DirectAwardJustificationCodeUnpublish | J34: TODO | L34: MG-NonPublishedInformation | M34: 6p | N34: /*/cac:TenderingProcess/cac:ProcessJustification[cbc:ProcessReasonCode/@listName='direct-award-justification']/ext:UBLExtensions/ext:UBLExtension/ext:ExtensionContent/efext:EformsExtension/efac:FieldsPrivacy[efbc:FieldIdentifierCode/text()='dir-awa-jus']/efbc:ReasonDescription | P34: efbc:ReasonDescription | T34: FALSE | U34: text-multilingual | V34: TEXT | X34: epo:NonPublishedInformation / rdf:langString | Y34: ?this epo:hasConfidentialityJustification ?value .
A35: 1.4 | C35: BT-197(BT-136)-Procedure | D35: Unpublished Justification Code | E35: BT-197 | F35: =IF(C35="", "", OR( LEFT(C35,3)="ND-", LEFT(C35,4)="[ND-")) -> FALSE | G35: =IF(C35="", "", NOT(F35)) -> TRUE | I35: ND-DirectAwardJustificationCodeUnpublish | J35: TODO | L35: MG-NonPublishedInformation | M35: 6p | N35: /*/cac:TenderingProcess/cac:ProcessJustification[cbc:ProcessReasonCode/@listName='direct-award-justification']/ext:UBLExtensions/ext:UBLExtension/ext:ExtensionContent/efext:EformsExtension/efac:FieldsPrivacy[efbc:FieldIdentifierCode/text()='dir-awa-jus']/cbc:ReasonCode | P35: cbc:ReasonCode | T35: FALSE | U35: code | V35: CODE | W35: non-publication-justification | X35: epo:NonPublishedInformation / at-voc:non-publication-justification | Y35: ?this epo:hasNonPublicationJustification ?value .
A36: 1.4 | B36: 1.5 | C36: BT-198(BT-136)-Procedure | D36: Unpublished Accessibility Date | E36: BT-198 | F36: =IF(C36="", "", OR( LEFT(C36,3)="ND-", LEFT(C36,4)="[ND-")) -> FALSE | G36: =IF(C36="", "", NOT(F36)) -> TRUE | I36: ND-DirectAwardJustificationCodeUnpublish | J36: TODO | L36: MG-NonPublishedInformation | M36: 6p | N36: /*/cac:TenderingProcess/cac:ProcessJustification[cbc:ProcessReasonCode/@listName='direct-award-justification']/ext:UBLExtensions/ext:UBLExtension/ext:ExtensionContent/efext:EformsExtension/efac:FieldsPrivacy[efbc:FieldIdentifierCode/text()='dir-awa-jus']/efbc:PublicationDate | P36: efbc:PublicationDate | T36: FALSE | U36: date | V36: DATE | X36: epo:NonPublishedInformation / xsd:date | Y36: ?this epo:hasAccessibilityDate ?value .
A37: 1.6 | C37: BT-198(BT-136)-Procedure | D37: Unpublished Access Date | E37: BT-198 | F37: =IF(C37="", "", OR( LEFT(C37,3)="ND-", LEFT(C37,4)="[ND-")) -> FALSE | G37: =IF(C37="", "", NOT(F37)) -> TRUE | I37: ND-DirectAwardJustificationCodeUnpublish | J37: TODO | L37: MG-NonPublishedInformation | M37: 6p | N37: /*/cac:TenderingProcess/cac:ProcessJustification[cbc:ProcessReasonCode/@listName='direct-award-justification']/ext:UBLExtensions/ext:UBLExtension/ext:ExtensionContent/efext:EformsExtension/efac:FieldsPrivacy[efbc:FieldIdentifierCode/text()='dir-awa-jus']/efbc:PublicationDate | P37: efbc:PublicationDate | T37: FALSE | U37: date | V37: DATE | X37: epo:NonPublishedInformation / xsd:date | Y37: ?this epo:hasAccessibilityDate ?value .
A38: 1.4 | C38: ND-DirectAwardJustificationTextUnpublish | F38: =IF(C38="", "", OR( LEFT(C38,3)="ND-", LEFT(C38,4)="[ND-")) -> TRUE | G38: =IF(C38="", "", NOT(F38)) -> FALSE | H38: ND-DirectAward | J38: TODO | L38: MG-DirectAwardTerm-concernsMaskedObject-NonPublishedInformation | M38: 6p | N38: /*/cac:TenderingProcess/cac:ProcessJustification[cbc:ProcessReasonCode/@listName='direct-award-justification']/ext:UBLExtensions/ext:UBLExtension/ext:ExtensionContent/efext:EformsExtension/efac:FieldsPrivacy[efbc:FieldIdentifierCode/text()='dir-awa-tex'] | P38: ext:UBLExtensions/ext:UBLExtension/ext:ExtensionContent/efext:EformsExtension/efac:FieldsPrivacy[efbc:FieldIdentifierCode/text()='dir-awa-tex'] | S38: FALSE | X38: epo:NonPublishedInformation / epo:DirectAwardTerm | Y38: ?this epo:concernsMaskedObject ?value .
A39: 1.4 | C39: ND-DirectAwardJustificationTextUnpublish | F39: =IF(C39="", "", OR( LEFT(C39,3)="ND-", LEFT(C39,4)="[ND-")) -> TRUE | G39: =IF(C39="", "", NOT(F39)) -> FALSE | H39: ND-DirectAward | J39: TODO | L39: MG-Notice-concernsNotice-NonPublishedInformation | M39: 6p | N39: /*/cac:TenderingProcess/cac:ProcessJustification[cbc:ProcessReasonCode/@listName='direct-award-justification']/ext:UBLExtensions/ext:UBLExtension/ext:ExtensionContent/efext:EformsExtension/efac:FieldsPrivacy[efbc:FieldIdentifierCode/text()='dir-awa-tex'] | P39: ext:UBLExtensions/ext:UBLExtension/ext:ExtensionContent/efext:EformsExtension/efac:FieldsPrivacy[efbc:FieldIdentifierCode/text()='dir-awa-tex'] | S39: FALSE | X39: epo:NonPublishedInformation / epo:Notice | Y39: ?this epo:concernsNotice ?value .
A40: 1.4 | C40: ND-DirectAwardJustificationTextUnpublish | F40: =IF(C40="", "", OR( LEFT(C40,3)="ND-", LEFT(C40,4)="[ND-")) -> TRUE | G40: =IF(C40="", "", NOT(F40)) -> FALSE | H40: ND-DirectAward | J40: TODO | L40: MG-DirectAwardTerm-isSubjectToTerm-Procedure | M40: 6p | N40: /*/cac:TenderingProcess/cac:ProcessJustification[cbc:ProcessReasonCode/@listName='direct-award-justification']/ext:UBLExtensions/ext:UBLExtension/ext:ExtensionContent/efext:EformsExtension/efac:FieldsPrivacy[efbc:FieldIdentifierCode/text()='dir-awa-tex'] | P40: ext:UBLExtensions/ext:UBLExtension/ext:ExtensionContent/efext:EformsExtension/efac:FieldsPrivacy[efbc:FieldIdentifierCode/text()='dir-awa-tex'] | S40: FALSE | X40: epo:Procedure / epo:DirectAwardTerm | Y40: ?this epo:isSubjectToTerm ?value .
...

Sheet TMInput
A1: File Name | B1: TriplesMap Name | C1: TriplesMap Label | D1: TriplesMap Subject Label | E1: Iterator | F1: Subject Condition | G1: Min SDK | H1: Max SDK | I1: Versioned TM | J1: MG Masked Object | K1: Node of Masked Object | L1: POM Masked Object Label | M1: POM Masked Object Comment | N1: TriplesMap Masked Object | O1: simplified Relative XPath | P1: joinCondition child | Q1: POM BT-195 Label | R1: POM BT-195 Comment | S1: POM BT-195 Condition | T1: POM BT-195 Value | U1: POM BT-197 Label | V1: POM BT-197 Comment | W1: POM BT-198 Label | X1: POM BT-198 Comment | Y1: BT-196 TriplesMap Name | Z1: BT-196 TriplesMap Iterator | AA1: POM BT-196 Label | AB1: POM BT-196 Comment | AC1: POM BT-196 Language Label | AD1: POM BT-196 Language Comment
A2: =IF(B2="---",B2, IF(D2="", "", D2 & (IF($I2, "_v" & IF($G2="", "1.3", $G2) & IF($H2="", "+", "-" & $H2), "") & ".rml.ttl"))) -> ND-ProcedureFeaturesUnpublish.rml.ttl | B2: =IF(MasterCMCopy!$X2="","---", "tedm:" & IF(LEFT(MasterCMCopy!$C2, 3)="ND-", IF(LEFT(MasterCMCopy!$C6, 3)="ND-", MasterCMCopy!$L8, MasterCMCopy!$L6) & "-" & MasterCMCopy!$C2, MasterCMCopy!$L2 & "-" & MasterCMCopy!$I2)) -> tedm:MG-NonPublishedInformation-ND-ProcedureFeaturesUnpublish | C2: =IF(AND(LEFT(MasterCMCopy!$C2,6)="BT-195", OR(LEFT(MasterCMCopy!$C1,3)="ND-",$B2<>$B1)),MasterCMCopy!$L2,"") | D2: =IF(AND(LEFT(MasterCMCopy!$C2,3)="ND-", OR(MasterCMCopy!$N2<>MasterCMCopy!$N1, MasterCMCopy!$P2<>MasterCMCopy!$P1)),MasterCMCopy!$C2,"") -> ND-ProcedureFeaturesUnpublish | E2: =IF(AND(LEFT(MasterCMCopy!$C2,3)="ND-", OR(MasterCMCopy!$N2<>MasterCMCopy!$N1, MasterCMCopy!$P2<>MasterCMCopy!$P1)),MasterCMCopy!$N2,"") -> /*/cac:TenderingProcess/ext:UBLExtensions/ext:UBLExtension/ext:ExtensionContent/efext:EformsExtension/efac:FieldsPrivacy[efbc:FieldIdentifierCode/text()='pro-fea'] | F2: =IFERROR(__xludf.DUMMYFUNCTION("IF($E2="""", """", REGEXEXTRACT($E2,""efbc:FieldIdentifierCode[^\]]+""))"),"efbc:FieldIdentifierCode/text()='pro-fea'") -> efbc:FieldIdentifierCode/text()='pro-fea' | G2: =MasterCMCopy!A2 -> 1.4 | H2: =MasterCMCopy!B2 | J2: =IF(LEFT(MasterCMCopy!$C2,3)="ND-", IF(LEFT(MasterCMCopy!$X2,10)<>"epo:NonPub", MasterCMCopy!$L2, IF(RIGHT(MasterCMCopy!$X2,13)="epo:Procedure", "MG-Procedure", "")), "") -> MG-Procedure | K2: =IF($J2="", "", IF($J2="MG-Procedure", "ND-Root", MasterCMCopy!$H2)) -> ND-Root | L2: =IF($J2="", "", MasterCMCopy!$C2 & " (concernsMaskedObject)") -> ND-ProcedureFeaturesUnpublish (concernsMaskedObject) | M2: =IFERROR(__xludf.DUMMYFUNCTION("IF($J2="""", """", ""Connection from NonPublishedInformation to "" & REGEXEXTRACT(MasterCMCopy!$X2, "".*:(.*)"") & "" under "" & $J2 & ""_"" & $K2)"),"Connection from NonPublishedInformation to Procedure under MG-Procedure_ND-Root") -> Connection from NonPublishedInformation to Procedure under MG-Procedure_ND-Root | N2: =IF($J2="", "", "tedm:" & $J2 & "_" & $K2) -> tedm:MG-Procedure_ND-Root | O2: =IFERROR(__xludf.DUMMYFUNCTION("IF($J2="""", """", IF($J2=""MG-Procedure"", """", REGEXREPLACE(MasterCMCopy!$P2,""\[[^\]]+\]"","""")))"),"") | P2: =IFERROR(__xludf.DUMMYFUNCTION("REGEXREPLACE($O2,""[^/]+"","".."")"),"") | Q2: =IF(AND(LEFT(MasterCMCopy!$C2,6)="BT-195", OR(MasterCMCopy!$O2<>MasterCMCopy!$O1,$G2<>$G1,$H2<>$H1)),MasterCMCopy!$C2,"") | R2: =IF(AND(LEFT(MasterCMCopy!$C2,6)="BT-195", OR(MasterCMCopy!$O2<>MasterCMCopy!$O1,$G2<>$G1,$H2<>$H1)), "The field " & MasterCMCopy!$C2 & ", " & MasterCMCopy!$D2 & ", specifies information to generate the URI of the masked property","") | S2: =IF(AND(LEFT(MasterCMCopy!$C2,6)="BT-195", OR(MasterCMCopy!$O2<>MasterCMCopy!$O1,$G2<>$G1,$H2<>$H1)),MasterCMCopy!$O2,"") | T2: =IFERROR(__xludf.DUMMYFUNCTION("IF(AND(LEFT(MasterCMCopy!$C2,6)=""BT-195"", MasterCMCopy!$O2<>MasterCMCopy!$O1),IFNA(REGEXEXTRACT(MasterCMCopy!$Y2,""<(.*)>""),""UNKNOWN""),"""")"),"") | U2: =IF(AND(LEFT(MasterCMCopy!$C2,6)="BT-197", MasterCMCopy!$C2<>MasterCMCopy!$C1),MasterCMCopy!$C2,"") | V2: =IF(AND(LEFT(MasterCMCopy!$C2,6)="BT-197", MasterCMCopy!$C2<>MasterCMCopy!$C1), "In " & MasterCMCopy!$C2 & ", " & MasterCMCopy!$D2 & ", we link to the at-voc:non-publication-justification controlled list","") | W2: =IF(AND(LEFT(MasterCMCopy!$C2,6)="BT-198", MasterCMCopy!$C2<>MasterCMCopy!$C1),MasterCMCopy!$C2,"") | X2: =IF(AND(LEFT(MasterCMCopy!$C2,6)="BT-198", MasterCMCopy!$C2<>MasterCMCopy!$C1), MasterCMCopy!$D2 & IF(AND(MasterCMCopy!$C2=MasterCMCopy!$C3, MasterCMCopy!$D2<>MasterCMCopy!$D3), (" (" & MasterCMCopy!$D3 & " below SDK 1.6)"), ""),"") | Y2: =REPLACE($B2, 1, LEN("tedm:MG"), "tedm:MG-langString-hasConfidentialityJustification-") -> tedm:MG-langString-hasConfidentialityJustification--NonPublishedInformation-ND-ProcedureFeaturesUnpublish | Z2: =IF($E2="", "", $E2 & "/efbc:ReasonDescription") -> /*/cac:TenderingProcess/ext:UBLExtensions/ext:UBLExtension/ext:ExtensionContent/efext:EformsExtension/efac:FieldsPrivacy[efbc:FieldIdentifierCode/text()='pro-fea']/efbc:ReasonDescription | AA2: =IF(AND(LEFT(MasterCMCopy!$C2,6)="BT-196", MasterCMCopy!$C2<>MasterCMCopy!$C1),MasterCMCopy!$C2,"") | AB2: =IF(AND(LEFT(MasterCMCopy!$C2,6)="BT-196", MasterCMCopy!$C2<>MasterCMCopy!$C1), MasterCMCopy!$D2 & " of " & MasterCMCopy!$L2 & " under " & MasterCMCopy!$I2,"") | AC2: =IF($AA2="", "", $AA2 & "-Language") | AD2: =IF($AB2="", "", "Language of " & $AB2)
A3: =IF(B3="---",B3, IF(D3="", "", D3 & (IF($I3, "_v" & IF($G3="", "1.3", $G3) & IF($H3="", "+", "-" & $H3), "") & ".rml.ttl"))) | B3: =IF(MasterCMCopy!$X3="","---", "tedm:" & IF(LEFT(MasterCMCopy!$C3, 3)="ND-", IF(LEFT(MasterCMCopy!$C7, 3)="ND-", MasterCMCopy!$L9, MasterCMCopy!$L7) & "-" & MasterCMCopy!$C3, MasterCMCopy!$L3 & "-" & MasterCMCopy!$I3)) -> tedm:MG-NonPublishedInformation-ND-ProcedureFeaturesUnpublish | C3: =IF(AND(LEFT(MasterCMCopy!$C3,6)="BT-195", OR(LEFT(MasterCMCopy!$C2,3)="ND-",$B3<>$B2)),MasterCMCopy!$L3,"") | D3: =IF(AND(LEFT(MasterCMCopy!$C3,3)="ND-", OR(MasterCMCopy!$N3<>MasterCMCopy!$N2, MasterCMCopy!$P3<>MasterCMCopy!$P2)),MasterCMCopy!$C3,"") | E3: =IF(AND(LEFT(MasterCMCopy!$C3,3)="ND-", OR(MasterCMCopy!$N3<>MasterCMCopy!$N2, MasterCMCopy!$P3<>MasterCMCopy!$P2)),MasterCMCopy!$N3,"") | F3: =IFERROR(__xludf.DUMMYFUNCTION("IF($E3="""", """", REGEXEXTRACT($E3,""efbc:FieldIdentifierCode[^\]]+""))"),"") | G3: =MasterCMCopy!A3 -> 1.4 | H3: =MasterCMCopy!B3 | J3: =IF(LEFT(MasterCMCopy!$C3,3)="ND-", IF(LEFT(MasterCMCopy!$X3,10)<>"epo:NonPub", MasterCMCopy!$L3, IF(RIGHT(MasterCMCopy!$X3,13)="epo:Procedure", "MG-Procedure", "")), "") | K3: =IF(J3="", "", IF(J3="MG-Procedure", "ND-Root", MasterCMCopy!H3)) | L3: =IF($J3="", "", MasterCMCopy!$C3 & " (concernsMaskedObject)") | M3: =IFERROR(__xludf.DUMMYFUNCTION("IF($J3="""", """", ""Connection from NonPublishedInformation to "" & REGEXEXTRACT(MasterCMCopy!$X3, "".*:(.*)"") & "" under "" & $J3 & ""_"" & $K3)"),"") | N3: =IF(J3="", "", "tedm:" & J3 & "_" & K3) | O3: =IFERROR(__xludf.DUMMYFUNCTION("IF($J3="""", """", IF($J3=""MG-Procedure"", """", REGEXREPLACE(MasterCMCopy!$P3,""\[[^\]]+\]"","""")))"),"") | P3: =IFERROR(__xludf.DUMMYFUNCTION("REGEXREPLACE($O3,""[^/]+"","".."")"),"") | Q3: =IF(AND(LEFT(MasterCMCopy!$C3,6)="BT-195", OR(MasterCMCopy!$O3<>MasterCMCopy!$O2,$G3<>$G2,$H3<>$H2)),MasterCMCopy!$C3,"") | R3: =IF(AND(LEFT(MasterCMCopy!$C3,6)="BT-195", OR(MasterCMCopy!$O3<>MasterCMCopy!$O2,$G3<>$G2,$H3<>$H2)), "The field " & MasterCMCopy!$C3 & ", " & MasterCMCopy!$D3 & ", specifies information to generate the URI of the masked property","") | S3: =IF(AND(LEFT(MasterCMCopy!$C3,6)="BT-195", OR(MasterCMCopy!$O3<>MasterCMCopy!$O2,$G3<>$G2,$H3<>$H2)),MasterCMCopy!$O3,"") | T3: =IFERROR(__xludf.DUMMYFUNCTION("IF(AND(LEFT(MasterCMCopy!$C3,6)=""BT-195"", MasterCMCopy!$O3<>MasterCMCopy!$O2),IFNA(REGEXEXTRACT(MasterCMCopy!$Y3,""<(.*)>""),""UNKNOWN""),"""")"),"") | U3: =IF(AND(LEFT(MasterCMCopy!$C3,6)="BT-197", MasterCMCopy!$C3<>MasterCMCopy!$C2),MasterCMCopy!$C3,"") | V3: =IF(AND(LEFT(MasterCMCopy!$C3,6)="BT-197", MasterCMCopy!$C3<>MasterCMCopy!$C2), "In " & MasterCMCopy!$C3 & ", " & MasterCMCopy!$D3 & ", we link to the at-voc:non-publication-justification controlled list","") | W3: =IF(AND(LEFT(MasterCMCopy!$C3,6)="BT-198", MasterCMCopy!$C3<>MasterCMCopy!$C2),MasterCMCopy!$C3,"") | X3: =IF(AND(LEFT(MasterCMCopy!$C3,6)="BT-198", MasterCMCopy!$C3<>MasterCMCopy!$C2), MasterCMCopy!$D3 & IF(AND(MasterCMCopy!$C3=MasterCMCopy!$C4, MasterCMCopy!$D3<>MasterCMCopy!$D4), (" (" & MasterCMCopy!$D4 & " below SDK 1.6)"), ""),"") | Y3: =REPLACE($B3, 1, LEN("tedm:MG"), "tedm:MG-langString-hasConfidentialityJustification-") -> tedm:MG-langString-hasConfidentialityJustification--NonPublishedInformation-ND-ProcedureFeaturesUnpublish | Z3: =IF($E3="", "", $E3 & "/efbc:ReasonDescription") | AA3: =IF(AND(LEFT(MasterCMCopy!$C3,6)="BT-196", MasterCMCopy!$C3<>MasterCMCopy!$C2),MasterCMCopy!$C3,"") | AB3: =IF(AND(LEFT(MasterCMCopy!$C3,6)="BT-196", MasterCMCopy!$C3<>MasterCMCopy!$C2), MasterCMCopy!$D3 & " of " & MasterCMCopy!$L3 & " under " & MasterCMCopy!$I3,"") | AC3: =IF($AA3="", "", $AA3 & "-Language") | AD3: =IF($AB3="", "", "Language of " & $AB3)
A4: =IF(B4="---",B4, IF(D4="", "", D4 & (IF($I4, "_v" & IF($G4="", "1.3", $G4) & IF($H4="", "+", "-" & $H4), "") & ".rml.ttl"))) | B4: =IF(MasterCMCopy!$X4="","---", "tedm:" & IF(LEFT(MasterCMCopy!$C4, 3)="ND-", IF(LEFT(MasterCMCopy!$C8, 3)="ND-", MasterCMCopy!$L10, MasterCMCopy!$L8) & "-" & MasterCMCopy!$C4, MasterCMCopy!$L4 & "-" & MasterCMCopy!$I4)) -> tedm:MG-NonPublishedInformation-ND-ProcedureFeaturesUnpublish | C4: =IF(AND(LEFT(MasterCMCopy!$C4,6)="BT-195", OR(LEFT(MasterCMCopy!$C3,3)="ND-",$B4<>$B3)),MasterCMCopy!$L4,"") -> MG-NonPublishedInformation | D4: =IF(AND(LEFT(MasterCMCopy!$C4,3)="ND-", OR(MasterCMCopy!$N4<>MasterCMCopy!$N3, MasterCMCopy!$P4<>MasterCMCopy!$P3)),MasterCMCopy!$C4,"") | E4: =IF(AND(LEFT(MasterCMCopy!$C4,3)="ND-", OR(MasterCMCopy!$N4<>MasterCMCopy!$N3, MasterCMCopy!$P4<>MasterCMCopy!$P3)),MasterCMCopy!$N4,"") | F4: =IFERROR(__xludf.DUMMYFUNCTION("IF($E4="""", """", REGEXEXTRACT($E4,""efbc:FieldIdentifierCode[^\]]+""))"),"") | G4: =MasterCMCopy!A4 -> 1.4 | H4: =MasterCMCopy!B4 | J4: =IF(LEFT(MasterCMCopy!$C4,3)="ND-", IF(LEFT(MasterCMCopy!$X4,10)<>"epo:NonPub", MasterCMCopy!$L4, IF(RIGHT(MasterCMCopy!$X4,13)="epo:Procedure", "MG-Procedure", "")), "") | K4: =IF(J4="", "", IF(J4="MG-Procedure", "ND-Root", MasterCMCopy!H4)) | L4: =IF($J4="", "", MasterCMCopy!$C4 & " (concernsMaskedObject)") | M4: =IFERROR(__xludf.DUMMYFUNCTION("IF($J4="""", """", ""Connection from NonPublishedInformation to "" & REGEXEXTRACT(MasterCMCopy!$X4, "".*:(.*)"") & "" under "" & $J4 & ""_"" & $K4)"),"") | N4: =IF(J4="", "", "tedm:" & J4 & "_" & K4) | O4: =IFERROR(__xludf.DUMMYFUNCTION("IF($J4="""", """", IF($J4=""MG-Procedure"", """", REGEXREPLACE(MasterCMCopy!$P4,""\[[^\]]+\]"","""")))"),"") | P4: =IFERROR(__xludf.DUMMYFUNCTION("REGEXREPLACE($O4,""[^/]+"","".."")"),"") | Q4: =IF(AND(LEFT(MasterCMCopy!$C4,6)="BT-195", OR(MasterCMCopy!$O4<>MasterCMCopy!$O3,$G4<>$G3,$H4<>$H3)),MasterCMCopy!$C4,"") -> BT-195(BT-88)-Procedure | R4: =IF(AND(LEFT(MasterCMCopy!$C4,6)="BT-195", OR(MasterCMCopy!$O4<>MasterCMCopy!$O3,$G4<>$G3,$H4<>$H3)), "The field " & MasterCMCopy!$C4 & ", " & MasterCMCopy!$D4 & ", specifies information to generate the URI of the masked property","") -> The field BT-195(BT-88)-Procedure, Unpublished Identifier, specifies information to generate the URI of the masked property | S4: =IF(AND(LEFT(MasterCMCopy!$C4,6)="BT-195", OR(MasterCMCopy!$O4<>MasterCMCopy!$O3,$G4<>$G3,$H4<>$H3)),MasterCMCopy!$O4,"") -> efbc:FieldIdentifierCode/text() = 'pro-fea' | T4: =IFERROR(__xludf.DUMMYFUNCTION("IF(AND(LEFT(MasterCMCopy!$C4,6)=""BT-195"", MasterCMCopy!$O4<>MasterCMCopy!$O3),IFNA(REGEXEXTRACT(MasterCMCopy!$Y4,""<(.*)>""),""UNKNOWN""),"""")"),"http://data.europa.eu/a4g/ontology#hasMainFeature") -> http://data.europa.eu/a4g/ontology#hasMainFeature | U4: =IF(AND(LEFT(MasterCMCopy!$C4,6)="BT-197", MasterCMCopy!$C4<>MasterCMCopy!$C3),MasterCMCopy!$C4,"") | V4: =IF(AND(LEFT(MasterCMCopy!$C4,6)="BT-197", MasterCMCopy!$C4<>MasterCMCopy!$C3), "In " & MasterCMCopy!$C4 & ", " & MasterCMCopy!$D4 & ", we link to the at-voc:non-publication-justification controlled list","") | W4: =IF(AND(LEFT(MasterCMCopy!$C4,6)="BT-198", MasterCMCopy!$C4<>MasterCMCopy!$C3),MasterCMCopy!$C4,"") | X4: =IF(AND(LEFT(MasterCMCopy!$C4,6)="BT-198", MasterCMCopy!$C4<>MasterCMCopy!$C3), MasterCMCopy!$D4 & IF(AND(MasterCMCopy!$C4=MasterCMCopy!$C5, MasterCMCopy!$D4<>MasterCMCopy!$D5), (" (" & MasterCMCopy!$D5 & " below SDK 1.6)"), ""),"") | Y4: =REPLACE($B4, 1, LEN("tedm:MG"), "tedm:MG-langString-hasConfidentialityJustification-") -> tedm:MG-langString-hasConfidentialityJustification--NonPublishedInformation-ND-ProcedureFeaturesUnpublish | Z4: =IF($E4="", "", $E4 & "/efbc:ReasonDescription") | AA4: =IF(AND(LEFT(MasterCMCopy!$C4,6)="BT-196", MasterCMCopy!$C4<>MasterCMCopy!$C3),MasterCMCopy!$C4,"") | AB4: =IF(AND(LEFT(MasterCMCopy!$C4,6)="BT-196", MasterCMCopy!$C4<>MasterCMCopy!$C3), MasterCMCopy!$D4 & " of " & MasterCMCopy!$L4 & " under " & MasterCMCopy!$I4,"") | AC4: =IF($AA4="", "", $AA4 & "-Language") | AD4: =IF($AB4="", "", "Language of " & $AB4)
A5: =IF(B5="---",B5, IF(D5="", "", D5 & (IF($I5, "_v" & IF($G5="", "1.3", $G5) & IF($H5="", "+", "-" & $H5), "") & ".rml.ttl"))) | B5: =IF(MasterCMCopy!$X5="","---", "tedm:" & IF(LEFT(MasterCMCopy!$C5, 3)="ND-", IF(LEFT(MasterCMCopy!$C9, 3)="ND-", MasterCMCopy!$L11, MasterCMCopy!$L9) & "-" & MasterCMCopy!$C5, MasterCMCopy!$L5 & "-" & MasterCMCopy!$I5)) -> tedm:MG-NonPublishedInformation-ND-ProcedureFeaturesUnpublish | C5: =IF(AND(LEFT(MasterCMCopy!$C5,6)="BT-195", OR(LEFT(MasterCMCopy!$C4,3)="ND-",$B5<>$B4)),MasterCMCopy!$L5,"") | D5: =IF(AND(LEFT(MasterCMCopy!$C5,3)="ND-", OR(MasterCMCopy!$N5<>MasterCMCopy!$N4, MasterCMCopy!$P5<>MasterCMCopy!$P4)),MasterCMCopy!$C5,"") | E5: =IF(AND(LEFT(MasterCMCopy!$C5,3)="ND-", OR(MasterCMCopy!$N5<>MasterCMCopy!$N4, MasterCMCopy!$P5<>MasterCMCopy!$P4)),MasterCMCopy!$N5,"") | F5: =IFERROR(__xludf.DUMMYFUNCTION("IF($E5="""", """", REGEXEXTRACT($E5,""efbc:FieldIdentifierCode[^\]]+""))"),"") | G5: =MasterCMCopy!A5 -> 1.4 | H5: =MasterCMCopy!B5 | J5: =IF(LEFT(MasterCMCopy!$C5,3)="ND-", IF(LEFT(MasterCMCopy!$X5,10)<>"epo:NonPub", MasterCMCopy!$L5, IF(RIGHT(MasterCMCopy!$X5,13)="epo:Procedure", "MG-Procedure", "")), "") | K5: =IF(J5="", "", IF(J5="MG-Procedure", "ND-Root", MasterCMCopy!H5)) | L5: =IF($J5="", "", MasterCMCopy!$C5 & " (concernsMaskedObject)") | M5: =IFERROR(__xludf.DUMMYFUNCTION("IF($J5="""", """", ""Connection from NonPublishedInformation to "" & REGEXEXTRACT(MasterCMCopy!$X5, "".*:(.*)"") & "" under "" & $J5 & ""_"" & $K5)"),"") | N5: =IF(J5="", "", "tedm:" & J5 & "_" & K5) | O5: =IFERROR(__xludf.DUMMYFUNCTION("IF($J5="""", """", IF($J5=""MG-Procedure"", """", REGEXREPLACE(MasterCMCopy!$P5,""\[[^\]]+\]"","""")))"),"") | P5: =IFERROR(__xludf.DUMMYFUNCTION("REGEXREPLACE($O5,""[^/]+"","".."")"),"") | Q5: =IF(AND(LEFT(MasterCMCopy!$C5,6)="BT-195", OR(MasterCMCopy!$O5<>MasterCMCopy!$O4,$G5<>$G4,$H5<>$H4)),MasterCMCopy!$C5,"") | R5: =IF(AND(LEFT(MasterCMCopy!$C5,6)="BT-195", OR(MasterCMCopy!$O5<>MasterCMCopy!$O4,$G5<>$G4,$H5<>$H4)), "The field " & MasterCMCopy!$C5 & ", " & MasterCMCopy!$D5 & ", specifies information to generate the URI of the masked property","") | S5: =IF(AND(LEFT(MasterCMCopy!$C5,6)="BT-195", OR(MasterCMCopy!$O5<>MasterCMCopy!$O4,$G5<>$G4,$H5<>$H4)),MasterCMCopy!$O5,"") | T5: =IFERROR(__xludf.DUMMYFUNCTION("IF(AND(LEFT(MasterCMCopy!$C5,6)=""BT-195"", MasterCMCopy!$O5<>MasterCMCopy!$O4),IFNA(REGEXEXTRACT(MasterCMCopy!$Y5,""<(.*)>""),""UNKNOWN""),"""")"),"") | U5: =IF(AND(LEFT(MasterCMCopy!$C5,6)="BT-197", MasterCMCopy!$C5<>MasterCMCopy!$C4),MasterCMCopy!$C5,"") | V5: =IF(AND(LEFT(MasterCMCopy!$C5,6)="BT-197", MasterCMCopy!$C5<>MasterCMCopy!$C4), "In " & MasterCMCopy!$C5 & ", " & MasterCMCopy!$D5 & ", we link to the at-voc:non-publication-justification controlled list","") | W5: =IF(AND(LEFT(MasterCMCopy!$C5,6)="BT-198", MasterCMCopy!$C5<>MasterCMCopy!$C4),MasterCMCopy!$C5,"") | X5: =IF(AND(LEFT(MasterCMCopy!$C5,6)="BT-198", MasterCMCopy!$C5<>MasterCMCopy!$C4), MasterCMCopy!$D5 & IF(AND(MasterCMCopy!$C5=MasterCMCopy!$C6, MasterCMCopy!$D5<>MasterCMCopy!$D6), (" (" & MasterCMCopy!$D6 & " below SDK 1.6)"), ""),"") | Y5: =REPLACE($B5, 1, LEN("tedm:MG"), "tedm:MG-langString-hasConfidentialityJustification-") -> tedm:MG-langString-hasConfidentialityJustification--NonPublishedInformation-ND-ProcedureFeaturesUnpublish | Z5: =IF($E5="", "", $E5 & "/efbc:ReasonDescription") | AA5: =IF(AND(LEFT(MasterCMCopy!$C5,6)="BT-196", MasterCMCopy!$C5<>MasterCMCopy!$C4),MasterCMCopy!$C5,"") -> BT-196(BT-88)-Procedure | AB5: =IF(AND(LEFT(MasterCMCopy!$C5,6)="BT-196", MasterCMCopy!$C5<>MasterCMCopy!$C4), MasterCMCopy!$D5 & " of " & MasterCMCopy!$L5 & " under " & MasterCMCopy!$I5,"") -> Unpublished Justification Description of MG-NonPublishedInformation under ND-ProcedureFeaturesUnpublish | AC5: =IF($AA5="", "", $AA5 & "-Language") -> BT-196(BT-88)-Procedure-Language | AD5: =IF($AB5="", "", "Language of " & $AB5) -> Language of Unpublished Justification Description of MG-NonPublishedInformation under ND-ProcedureFeaturesUnpublish
A6: =IF(B6="---",B6, IF(D6="", "", D6 & (IF($I6, "_v" & IF($G6="", "1.3", $G6) & IF($H6="", "+", "-" & $H6), "") & ".rml.ttl"))) | B6: =IF(MasterCMCopy!$X6="","---", "tedm:" & IF(LEFT(MasterCMCopy!$C6, 3)="ND-", IF(LEFT(MasterCMCopy!$C10, 3)="ND-", MasterCMCopy!$L12, MasterCMCopy!$L10) & "-" & MasterCMCopy!$C6, MasterCMCopy!$L6 & "-" & MasterCMCopy!$I6)) -> tedm:MG-NonPublishedInformation-ND-ProcedureFeaturesUnpublish | C6: =IF(AND(LEFT(MasterCMCopy!$C6,6)="BT-195", OR(LEFT(MasterCMCopy!$C5,3)="ND-",$B6<>$B5)),MasterCMCopy!$L6,"") | D6: =IF(AND(LEFT(MasterCMCopy!$C6,3)="ND-", OR(MasterCMCopy!$N6<>MasterCMCopy!$N5, MasterCMCopy!$P6<>MasterCMCopy!$P5)),MasterCMCopy!$C6,"") | E6: =IF(AND(LEFT(MasterCMCopy!$C6,3)="ND-", OR(MasterCMCopy!$N6<>MasterCMCopy!$N5, MasterCMCopy!$P6<>MasterCMCopy!$P5)),MasterCMCopy!$N6,"") | F6: =IFERROR(__xludf.DUMMYFUNCTION("IF($E6="""", """", REGEXEXTRACT($E6,""efbc:FieldIdentifierCode[^\]]+""))"),"") | G6: =MasterCMCopy!A6 -> 1.4 | H6: =MasterCMCopy!B6 | J6: =IF(LEFT(MasterCMCopy!$C6,3)="ND-", IF(LEFT(MasterCMCopy!$X6,10)<>"epo:NonPub", MasterCMCopy!$L6, IF(RIGHT(MasterCMCopy!$X6,13)="epo:Procedure", "MG-Procedure", "")), "") | K6: =IF(J6="", "", IF(J6="MG-Procedure", "ND-Root", MasterCMCopy!H6)) | L6: =IF($J6="", "", MasterCMCopy!$C6 & " (concernsMaskedObject)") | M6: =IFERROR(__xludf.DUMMYFUNCTION("IF($J6="""", """", ""Connection from NonPublishedInformation to "" & REGEXEXTRACT(MasterCMCopy!$X6, "".*:(.*)"") & "" under "" & $J6 & ""_"" & $K6)"),"") | N6: =IF(J6="", "", "tedm:" & J6 & "_" & K6) | O6: =IFERROR(__xludf.DUMMYFUNCTION("IF($J6="""", """", IF($J6=""MG-Procedure"", """", REGEXREPLACE(MasterCMCopy!$P6,""\[[^\]]+\]"","""")))"),"") | P6: =IFERROR(__xludf.DUMMYFUNCTION("REGEXREPLACE($O6,""[^/]+"","".."")"),"") | Q6: =IF(AND(LEFT(MasterCMCopy!$C6,6)="BT-195", OR(MasterCMCopy!$O6<>MasterCMCopy!$O5,$G6<>$G5,$H6<>$H5)),MasterCMCopy!$C6,"") | R6: =IF(AND(LEFT(MasterCMCopy!$C6,6)="BT-195", OR(MasterCMCopy!$O6<>MasterCMCopy!$O5,$G6<>$G5,$H6<>$H5)), "The field " & MasterCMCopy!$C6 & ", " & MasterCMCopy!$D6 & ", specifies information to generate the URI of the masked property","") | S6: =IF(AND(LEFT(MasterCMCopy!$C6,6)="BT-195", OR(MasterCMCopy!$O6<>MasterCMCopy!$O5,$G6<>$G5,$H6<>$H5)),MasterCMCopy!$O6,"") | T6: =IFERROR(__xludf.DUMMYFUNCTION("IF(AND(LEFT(MasterCMCopy!$C6,6)=""BT-195"", MasterCMCopy!$O6<>MasterCMCopy!$O5),IFNA(REGEXEXTRACT(MasterCMCopy!$Y6,""<(.*)>""),""UNKNOWN""),"""")"),"") | U6: =IF(AND(LEFT(MasterCMCopy!$C6,6)="BT-197", MasterCMCopy!$C6<>MasterCMCopy!$C5),MasterCMCopy!$C6,"") -> BT-197(BT-88)-Procedure | V6: =IF(AND(LEFT(MasterCMCopy!$C6,6)="BT-197", MasterCMCopy!$C6<>MasterCMCopy!$C5), "In " & MasterCMCopy!$C6 & ", " & MasterCMCopy!$D6 & ", we link to the at-voc:non-publication-justification controlled list","") -> In BT-197(BT-88)-Procedure, Unpublished Justification Code, we link to the at-voc:non-publication-justification controlled list | W6: =IF(AND(LEFT(MasterCMCopy!$C6,6)="BT-198", MasterCMCopy!$C6<>MasterCMCopy!$C5),MasterCMCopy!$C6,"") | X6: =IF(AND(LEFT(MasterCMCopy!$C6,6)="BT-198", MasterCMCopy!$C6<>MasterCMCopy!$C5), MasterCMCopy!$D6 & IF(AND(MasterCMCopy!$C6=MasterCMCopy!$C7, MasterCMCopy!$D6<>MasterCMCopy!$D7), (" (" & MasterCMCopy!$D7 & " below SDK 1.6)"), ""),"") | Y6: =REPLACE($B6, 1, LEN("tedm:MG"), "tedm:MG-langString-hasConfidentialityJustification-") -> tedm:MG-langString-hasConfidentialityJustification--NonPublishedInformation-ND-ProcedureFeaturesUnpublish | Z6: =IF($E6="", "", $E6 & "/efbc:ReasonDescription") | AA6: =IF(AND(LEFT(MasterCMCopy!$C6,6)="BT-196", MasterCMCopy!$C6<>MasterCMCopy!$C5),MasterCMCopy!$C6,"") | AB6: =IF(AND(LEFT(MasterCMCopy!$C6,6)="BT-196", MasterCMCopy!$C6<>MasterCMCopy!$C5), MasterCMCopy!$D6 & " of " & MasterCMCopy!$L6 & " under " & MasterCMCopy!$I6,"") | AC6: =IF($AA6="", "", $AA6 & "-Language") | AD6: =IF($AB6="", "", "Language of " & $AB6)
A7: =IF(B7="---",B7, IF(D7="", "", D7 & (IF($I7, "_v" & IF($G7="", "1.3", $G7) & IF($H7="", "+", "-" & $H7), "") & ".rml.ttl"))) | B7: =IF(MasterCMCopy!$X7="","---", "tedm:" & IF(LEFT(MasterCMCopy!$C7, 3)="ND-", IF(LEFT(MasterCMCopy!$C11, 3)="ND-", MasterCMCopy!$L13, MasterCMCopy!$L11) & "-" & MasterCMCopy!$C7, MasterCMCopy!$L7 & "-" & MasterCMCopy!$I7)) -> tedm:MG-NonPublishedInformation-ND-ProcedureFeaturesUnpublish | C7: =IF(AND(LEFT(MasterCMCopy!$C7,6)="BT-195", OR(LEFT(MasterCMCopy!$C6,3)="ND-",$B7<>$B6)),MasterCMCopy!$L7,"") | D7: =IF(AND(LEFT(MasterCMCopy!$C7,3)="ND-", OR(MasterCMCopy!$N7<>MasterCMCopy!$N6, MasterCMCopy!$P7<>MasterCMCopy!$P6)),MasterCMCopy!$C7,"") | E7: =IF(AND(LEFT(MasterCMCopy!$C7,3)="ND-", OR(MasterCMCopy!$N7<>MasterCMCopy!$N6, MasterCMCopy!$P7<>MasterCMCopy!$P6)),MasterCMCopy!$N7,"") | F7: =IFERROR(__xludf.DUMMYFUNCTION("IF($E7="""", """", REGEXEXTRACT($E7,""efbc:FieldIdentifierCode[^\]]+""))"),"") | G7: =MasterCMCopy!A7 -> 1.4 | H7: =MasterCMCopy!B7 -> 1.5 | J7: =IF(LEFT(MasterCMCopy!$C7,3)="ND-", IF(LEFT(MasterCMCopy!$X7,10)<>"epo:NonPub", MasterCMCopy!$L7, IF(RIGHT(MasterCMCopy!$X7,13)="epo:Procedure", "MG-Procedure", "")), "") | K7: =IF(J7="", "", IF(J7="MG-Procedure", "ND-Root", MasterCMCopy!H7)) | L7: =IF($J7="", "", MasterCMCopy!$C7 & " (concernsMaskedObject)") | M7: =IFERROR(__xludf.DUMMYFUNCTION("IF($J7="""", """", ""Connection from NonPublishedInformation to "" & REGEXEXTRACT(MasterCMCopy!$X7, "".*:(.*)"") & "" under "" & $J7 & ""_"" & $K7)"),"") | N7: =IF(J7="", "", "tedm:" & J7 & "_" & K7) | O7: =IFERROR(__xludf.DUMMYFUNCTION("IF($J7="""", """", IF($J7=""MG-Procedure"", """", REGEXREPLACE(MasterCMCopy!$P7,""\[[^\]]+\]"","""")))"),"") | P7: =IFERROR(__xludf.DUMMYFUNCTION("REGEXREPLACE($O7,""[^/]+"","".."")"),"") | Q7: =IF(AND(LEFT(MasterCMCopy!$C7,6)="BT-195", OR(MasterCMCopy!$O7<>MasterCMCopy!$O6,$G7<>$G6,$H7<>$H6)),MasterCMCopy!$C7,"") | R7: =IF(AND(LEFT(MasterCMCopy!$C7,6)="BT-195", OR(MasterCMCopy!$O7<>MasterCMCopy!$O6,$G7<>$G6,$H7<>$H6)), "The field " & MasterCMCopy!$C7 & ", " & MasterCMCopy!$D7 & ", specifies information to generate the URI of the masked property","") | S7: =IF(AND(LEFT(MasterCMCopy!$C7,6)="BT-195", OR(MasterCMCopy!$O7<>MasterCMCopy!$O6,$G7<>$G6,$H7<>$H6)),MasterCMCopy!$O7,"") | T7: =IFERROR(__xludf.DUMMYFUNCTION("IF(AND(LEFT(MasterCMCopy!$C7,6)=""BT-195"", MasterCMCopy!$O7<>MasterCMCopy!$O6),IFNA(REGEXEXTRACT(MasterCMCopy!$Y7,""<(.*)>""),""UNKNOWN""),"""")"),"") | U7: =IF(AND(LEFT(MasterCMCopy!$C7,6)="BT-197", MasterCMCopy!$C7<>MasterCMCopy!$C6),MasterCMCopy!$C7,"") | V7: =IF(AND(LEFT(MasterCMCopy!$C7,6)="BT-197", MasterCMCopy!$C7<>MasterCMCopy!$C6), "In " & MasterCMCopy!$C7 & ", " & MasterCMCopy!$D7 & ", we link to the at-voc:non-publication-justification controlled list","") | W7: =IF(AND(LEFT(MasterCMCopy!$C7,6)="BT-198", MasterCMCopy!$C7<>MasterCMCopy!$C6),MasterCMCopy!$C7,"") -> BT-198(BT-88)-Procedure | X7: =IF(AND(LEFT(MasterCMCopy!$C7,6)="BT-198", MasterCMCopy!$C7<>MasterCMCopy!$C6), MasterCMCopy!$D7 & IF(AND(MasterCMCopy!$C7=MasterCMCopy!$C8, MasterCMCopy!$D7<>MasterCMCopy!$D8), (" (" & MasterCMCopy!$D8 & " below SDK 1.6)"), ""),"") -> Unpublished Accessibility Date (Unpublished Access Date below SDK 1.6) | Y7: =REPLACE($B7, 1, LEN("tedm:MG"), "tedm:MG-langString-hasConfidentialityJustification-") -> tedm:MG-langString-hasConfidentialityJustification--NonPublishedInformation-ND-ProcedureFeaturesUnpublish | Z7: =IF($E7="", "", $E7 & "/efbc:ReasonDescription") | AA7: =IF(AND(LEFT(MasterCMCopy!$C7,6)="BT-196", MasterCMCopy!$C7<>MasterCMCopy!$C6),MasterCMCopy!$C7,"") | AB7: =IF(AND(LEFT(MasterCMCopy!$C7,6)="BT-196", MasterCMCopy!$C7<>MasterCMCopy!$C6), MasterCMCopy!$D7 & " of " & MasterCMCopy!$L7 & " under " & MasterCMCopy!$I7,"") | AC7: =IF($AA7="", "", $AA7 & "-Language") | AD7: =IF($AB7="", "", "Language of " & $AB7)
A8: =IF(B8="---",B8, IF(D8="", "", D8 & (IF($I8, "_v" & IF($G8="", "1.3", $G8) & IF($H8="", "+", "-" & $H8), "") & ".rml.ttl"))) | B8: =IF(MasterCMCopy!$X8="","---", "tedm:" & IF(LEFT(MasterCMCopy!$C8, 3)="ND-", IF(LEFT(MasterCMCopy!$C12, 3)="ND-", MasterCMCopy!$L14, MasterCMCopy!$L12) & "-" & MasterCMCopy!$C8, MasterCMCopy!$L8 & "-" & MasterCMCopy!$I8)) -> tedm:MG-NonPublishedInformation-ND-ProcedureFeaturesUnpublish | C8: =IF(AND(LEFT(MasterCMCopy!$C8,6)="BT-195", OR(LEFT(MasterCMCopy!$C7,3)="ND-",$B8<>$B7)),MasterCMCopy!$L8,"") | D8: =IF(AND(LEFT(MasterCMCopy!$C8,3)="ND-", OR(MasterCMCopy!$N8<>MasterCMCopy!$N7, MasterCMCopy!$P8<>MasterCMCopy!$P7)),MasterCMCopy!$C8,"") | E8: =IF(AND(LEFT(MasterCMCopy!$C8,3)="ND-", OR(MasterCMCopy!$N8<>MasterCMCopy!$N7, MasterCMCopy!$P8<>MasterCMCopy!$P7)),MasterCMCopy!$N8,"") | F8: =IFERROR(__xludf.DUMMYFUNCTION("IF($E8="""", """", REGEXEXTRACT($E8,""efbc:FieldIdentifierCode[^\]]+""))"),"") | G8: =MasterCMCopy!A8 -> 1.6 | H8: =MasterCMCopy!B8 | J8: =IF(LEFT(MasterCMCopy!$C8,3)="ND-", IF(LEFT(MasterCMCopy!$X8,10)<>"epo:NonPub", MasterCMCopy!$L8, IF(RIGHT(MasterCMCopy!$X8,13)="epo:Procedure", "MG-Procedure", "")), "") | K8: =IF(J8="", "", IF(J8="MG-Procedure", "ND-Root", MasterCMCopy!H8)) | L8: =IF($J8="", "", MasterCMCopy!$C8 & " (concernsMaskedObject)") | M8: =IFERROR(__xludf.DUMMYFUNCTION("IF($J8="""", """", ""Connection from NonPublishedInformation to "" & REGEXEXTRACT(MasterCMCopy!$X8, "".*:(.*)"") & "" under "" & $J8 & ""_"" & $K8)"),"") | N8: =IF(J8="", "", "tedm:" & J8 & "_" & K8) | O8: =IFERROR(__xludf.DUMMYFUNCTION("IF($J8="""", """", IF($J8=""MG-Procedure"", """", REGEXREPLACE(MasterCMCopy!$P8,""\[[^\]]+\]"","""")))"),"") | P8: =IFERROR(__xludf.DUMMYFUNCTION("REGEXREPLACE($O8,""[^/]+"","".."")"),"") | Q8: =IF(AND(LEFT(MasterCMCopy!$C8,6)="BT-195", OR(MasterCMCopy!$O8<>MasterCMCopy!$O7,$G8<>$G7,$H8<>$H7)),MasterCMCopy!$C8,"") | R8: =IF(AND(LEFT(MasterCMCopy!$C8,6)="BT-195", OR(MasterCMCopy!$O8<>MasterCMCopy!$O7,$G8<>$G7,$H8<>$H7)), "The field " & MasterCMCopy!$C8 & ", " & MasterCMCopy!$D8 & ", specifies information to generate the URI of the masked property","") | S8: =IF(AND(LEFT(MasterCMCopy!$C8,6)="BT-195", OR(MasterCMCopy!$O8<>MasterCMCopy!$O7,$G8<>$G7,$H8<>$H7)),MasterCMCopy!$O8,"") | T8: =IFERROR(__xludf.DUMMYFUNCTION("IF(AND(LEFT(MasterCMCopy!$C8,6)=""BT-195"", MasterCMCopy!$O8<>MasterCMCopy!$O7),IFNA(REGEXEXTRACT(MasterCMCopy!$Y8,""<(.*)>""),""UNKNOWN""),"""")"),"") | U8: =IF(AND(LEFT(MasterCMCopy!$C8,6)="BT-197", MasterCMCopy!$C8<>MasterCMCopy!$C7),MasterCMCopy!$C8,"") | V8: =IF(AND(LEFT(MasterCMCopy!$C8,6)="BT-197", MasterCMCopy!$C8<>MasterCMCopy!$C7), "In " & MasterCMCopy!$C8 & ", " & MasterCMCopy!$D8 & ", we link to the at-voc:non-publication-justification controlled list","") | W8: =IF(AND(LEFT(MasterCMCopy!$C8,6)="BT-198", MasterCMCopy!$C8<>MasterCMCopy!$C7),MasterCMCopy!$C8,"") | X8: =IF(AND(LEFT(MasterCMCopy!$C8,6)="BT-198", MasterCMCopy!$C8<>MasterCMCopy!$C7), MasterCMCopy!$D8 & IF(AND(MasterCMCopy!$C8=MasterCMCopy!$C9, MasterCMCopy!$D8<>MasterCMCopy!$D9), (" (" & MasterCMCopy!$D9 & " below SDK 1.6)"), ""),"") | Y8: =REPLACE($B8, 1, LEN("tedm:MG"), "tedm:MG-langString-hasConfidentialityJustification-") -> tedm:MG-langString-hasConfidentialityJustification--NonPublishedInformation-ND-ProcedureFeaturesUnpublish | Z8: =IF($E8="", "", $E8 & "/efbc:ReasonDescription") | AA8: =IF(AND(LEFT(MasterCMCopy!$C8,6)="BT-196", MasterCMCopy!$C8<>MasterCMCopy!$C7),MasterCMCopy!$C8,"") | AB8: =IF(AND(LEFT(MasterCMCopy!$C8,6)="BT-196", MasterCMCopy!$C8<>MasterCMCopy!$C7), MasterCMCopy!$D8 & " of " & MasterCMCopy!$L8 & " under " & MasterCMCopy!$I8,"") | AC8: =IF($AA8="", "", $AA8 & "-Language") | AD8: =IF($AB8="", "", "Language of " & $AB8)
